Workbook

Sheet dashboard

Sheet payroll_management_db
A1: Emp_ID | B1: First_Name | C1: Last_Name | D1: Department | E1: Designation | F1: Joining_Date | G1: Basic_Salary | H1: HRA | I1: Special_Allowance | J1: PF_Deduction | K1: Bank_Account_No | L1: Aadhar no
A2: EMP001 | B2: Rahul | C2: Sharma | D2: IT | E2: Manager | F2: 44470 | G2: 50000 | H2: =G2*16% -> 8000 | I2: =G2*5% -> 2500 | J2: =G2*3% -> 1500 | K2: HDFC0001234 | L2: 1234575755
A3: EMP002 | B3: Simran | C3: Kaur | D3: HR | E3: Executive | F3: 15/03/2022 | G3: 30000 | H3: =G3*16% -> 4800 | I3: =G3*5% -> 1500 | J3: =G3*3% -> 900 | K3: SBI0009876 | L3: 43477474743
A4: EMP003 | B4: Amit | C4: Singh | D4: Sales | E4: Lead | F4: 20/07/2020 | G4: 40000 | H4: =G4*16% -> 6400 | I4: =G4*5% -> 2000 | J4: =G4*3% -> 1200 | K4: ICICI0004567 | L4: 85720373731
A5: EMP004 | B5: Neha | C5: Gupta | D5: Admin | E5: Coordinator | F5: 45057 | G5: 25000 | H5: =G5*16% -> 4000 | I5: =G5*5% -> 1250 | J5: =G5*3% -> 750 | K5: PNB0003456 | L5: 56464643737
A6: EMP005 | B6: Vikram | C6: Joshi | D6: IT | E6: Developer | F6: 44532 | G6: 45000 | H6: =G6*16% -> 7200 | I6: =G6*5% -> 2250 | J6: =G6*3% -> 1350 | K6: HDFC0001235 | L6: 45558584844
A7: EMP006 | B7: Priya | C7: Verma | D7: Marketing | E7: Specialist | F7: 44935 | G7: 35000 | H7: =G7*16% -> 5600 | I7: =G7*5% -> 1750 | J7: =G7*3% -> 1050 | K7: AXIS0007890 | L7: 45454566
A8: EMP007 | B8: Ravi | C8: Kumar | D8: IT | E8: Tester | F8: 18/05/2022 | G8: 32000 | H8: =G8*16% -> 5120 | I8: =G8*5% -> 1600 | J8: =G8*3% -> 960 | K8: SBI0009877 | L8: 64546646464
A9: EMP008 | B9: Gurpreet | C9: Singh | D9: Operations | E9: Manager | F9: 14/06/2019 | G9: 48000 | H9: =G9*16% -> 7680 | I9: =G9*5% -> 2400 | J9: =G9*3% -> 1440 | K9: HDFC0001236 | L9: 64646464764
A10: EMP009 | B10: Aman | C10: Deep | D10: IT | E10: Developer | F10: 22/08/2022 | G10: 42000 | H10: =G10*16% -> 6720 | I10: =G10*5% -> 2100 | J10: =G10*3% -> 1260 | K10: PNB0003457 | L10: 5646466
A11: EMP010 | B11: Sonia | C11: Bajaj | D11: HR | E11: Manager | F11: 44146 | G11: 46000 | H11: =G11*16% -> 7360 | I11: =G11*5% -> 2300 | J11: =G11*3% -> 1380 | K11: ICICI0004568 | L11: 24424553253
A12: EMP011 | B12: Karan | C12: Malhotra | D12: Sales | E12: Executive | F12: 45537 | G12: 28000 | H12: =G12*16% -> 4480 | I12: =G12*5% -> 1400 | J12: =G12*3% -> 840 | K12: SBI0009878 | L12: 757557754
A13: EMP012 | B13: Pooja | C13: Rani | D13: Finance | E13: Analyst | F13: 30/01/2021 | G13: 38000 | H13: =G13*16% -> 6080 | I13: =G13*5% -> 1900 | J13: =G13*3% -> 1140 | K13: AXIS0007891 | L13: 46464646464
A14: EMP013 | B14: Harjit | C14: Singh | D14: Admin | E14: Assistant | F14: 17/04/2023 | G14: 22000 | H14: =G14*16% -> 3520 | I14: =G14*5% -> 1100 | J14: =G14*3% -> 660 | K14: HDFC0001237 | L14: 466464777
A15: EMP014 | B15: Manpreet | C15: Kaur | D15: Marketing | E15: Manager | F15: 25/12/2018 | G15: 55000 | H15: =G15*16% -> 8800 | I15: =G15*5% -> 2750 | J15: =G15*3% -> 1650 | K15: PNB0003458 | L15: 383838383
A16: EMP015 | B16: Rohit | C16: Bansal | D16: IT | E16: Support | F16: 44992 | G16: 26000 | H16: =G16*16% -> 4160 | I16: =G16*5% -> 1300 | J16: =G16*3% -> 780 | K16: SBI0009879 | L16: 858585884
J19: =G19*3% -> 0
J20: =G20*3% -> 0

Sheet salary_process
A1: Emp_ID | B1: First_Name | C1: Basic_Salary | D1: Payable_Days | E1: Calculated_Basic | F1: HRA | G1: ESI | H1: PF_Deduction | I1: Net_Salary
A2: EMP001 | B2: =VLOOKUP(A2,payroll_management_db!A:B,2,0) -> Rahul | C2: =VLOOKUP(A2,payroll_management_db!A:G,7,0) -> 50000 | D2: =VLOOKUP(A2,employee_payroll_system!A:M,13,0) -> 7 | E2: =ROUND((C2/31)*D2,2) -> 11290.32 | F2: =VLOOKUP(A2,payroll_management_db!A:H,8,0) -> 8000 | G2: =E2*3% -> 338.7096 | H2: =VLOOKUP(A2,payroll_management_db!A:J,10,0) -> 1500 | I2: =ROUND((E2+F2)-H2,2) -> 17790.32
A3: EMP002 | B3: =VLOOKUP(A3,payroll_management_db!A:B,2,0) -> Simran | C3: 30000 | D3: 6 | E3: =ROUND((C3/31)*D3,2) -> 5806.45 | F3: =VLOOKUP(A3,payroll_management_db!A:H,8,0) -> 4800 | G3: =E3*3% -> 174.1935 | H3: =VLOOKUP(A3,payroll_management_db!A:J,10,0) -> 900 | I3: =ROUND((E3+F3)-H3,2) -> 9706.45
A4: EMP003 | B4: =VLOOKUP(A4,payroll_management_db!A:B,2,0) -> Amit | C4: 40000 | D4: 7 | E4: =ROUND((C4/31)*D4,2) -> 9032.26 | F4: =VLOOKUP(A4,payroll_management_db!A:H,8,0) -> 6400 | G4: =E4*3% -> 270.9678 | H4: =VLOOKUP(A4,payroll_management_db!A:J,10,0) -> 1200 | I4: =ROUND((E4+F4)-H4,2) -> 14232.26
A5: EMP004 | B5: =VLOOKUP(A5,payroll_management_db!A:B,2,0) -> Neha | C5: 25000 | D5: 7 | E5: =ROUND((C5/31)*D5,2) -> 5645.16 | F5: =VLOOKUP(A5,payroll_management_db!A:H,8,0) -> 4000 | G5: =E5*3% -> 169.3548 | H5: =VLOOKUP(A5,payroll_management_db!A:J,10,0) -> 750 | I5: =ROUND((E5+F5)-H5,2) -> 8895.16
A6: EMP005 | B6: =VLOOKUP(A6,payroll_management_db!A:B,2,0) -> Vikram | C6: 45000 | D6: 7 | E6: =ROUND((C6/31)*D6,2) -> 10161.29 | F6: =VLOOKUP(A6,payroll_management_db!A:H,8,0) -> 7200 | G6: =E6*3% -> 304.8387 | H6: =VLOOKUP(A6,payroll_management_db!A:J,10,0) -> 1350 | I6: =ROUND((E6+F6)-H6,2) -> 16011.29
A7: EMP006 | B7: =VLOOKUP(A7,payroll_management_db!A:B,2,0) -> Priya | C7: 35000 | D7: 7 | E7: =ROUND((C7/31)*D7,2) -> 7903.23 | F7: =VLOOKUP(A7,payroll_management_db!A:H,8,0) -> 5600 | G7: =E7*3% -> 237.0969 | H7: =VLOOKUP(A7,payroll_management_db!A:J,10,0) -> 1050 | I7: =ROUND((E7+F7)-H7,2) -> 12453.23
A8: EMP007 | B8: =VLOOKUP(A8,payroll_management_db!A:B,2,0) -> Ravi | C8: 32000 | D8: 7 | E8: =ROUND((C8/31)*D8,2) -> 7225.81 | F8: =VLOOKUP(A8,payroll_management_db!A:H,8,0) -> 5120 | G8: =E8*3% -> 216.7743 | H8: =VLOOKUP(A8,payroll_management_db!A:J,10,0) -> 960 | I8: =ROUND((E8+F8)-H8,2) -> 11385.81
A9: EMP008 | B9: =VLOOKUP(A9,payroll_management_db!A:B,2,0) -> Gurpreet | C9: 48000 | D9: 6 | E9: =ROUND((C9/31)*D9,2) -> 9290.32 | F9: =VLOOKUP(A9,payroll_management_db!A:H,8,0) -> 7680 | G9: =E9*3% -> 278.7096 | H9: =VLOOKUP(A9,payroll_management_db!A:J,10,0) -> 1440 | I9: =ROUND((E9+F9)-H9,2) -> 15530.32
A10: EMP009 | B10: =VLOOKUP(A10,payroll_management_db!A:B,2,0) -> Aman | C10: 42000 | D10: 7 | E10: =ROUND((C10/31)*D10,2) -> 9483.87 | F10: =VLOOKUP(A10,payroll_management_db!A:H,8,0) -> 6720 | G10: =E10*3% -> 284.5161 | H10: =VLOOKUP(A10,payroll_management_db!A:J,10,0) -> 1260 | I10: =ROUND((E10+F10)-H10,2) -> 14943.87
A11: EMP010 | B11: =VLOOKUP(A11,payroll_management_db!A:B,2,0) -> Sonia | C11: 46000 | D11: 5 | E11: =ROUND((C11/31)*D11,2) -> 7419.35 | F11: =VLOOKUP(A11,payroll_management_db!A:H,8,0) -> 7360 | G11: =E11*3% -> 222.5805 | H11: =VLOOKUP(A11,payroll_management_db!A:J,10,0) -> 1380 | I11: =ROUND((E11+F11)-H11,2) -> 13399.35
A12: EMP011 | B12: =VLOOKUP(A12,payroll_management_db!A:B,2,0) -> Karan | C12: 28000 | D12: 7 | E12: =ROUND((C12/31)*D12,2) -> 6322.58 | F12: =VLOOKUP(A12,payroll_management_db!A:H,8,0) -> 4480 | G12: =E12*3% -> 189.6774 | H12: =VLOOKUP(A12,payroll_management_db!A:J,10,0) -> 840 | I12: =ROUND((E12+F12)-H12,2) -> 9962.58
A13: EMP012 | B13: =VLOOKUP(A13,payroll_management_db!A:B,2,0) -> Pooja | C13: 38000 | D13: 7 | E13: =ROUND((C13/31)*D13,2) -> 8580.65 | F13: =VLOOKUP(A13,payroll_management_db!A:H,8,0) -> 6080 | G13: =E13*3% -> 257.4195 | H13: =VLOOKUP(A13,payroll_management_db!A:J,10,0) -> 1140 | I13: =ROUND((E13+F13)-H13,2) -> 13520.65
A14: EMP013 | B14: =VLOOKUP(A14,payroll_management_db!A:B,2,0) -> Harjit | C14: 22000 | D14: 7 | E14: =ROUND((C14/31)*D14,2) -> 4967.74 | F14: =VLOOKUP(A14,payroll_management_db!A:H,8,0) -> 3520 | G14: =E14*3% -> 149.0322 | H14: =VLOOKUP(A14,payroll_management_db!A:J,10,0) -> 660 | I14: =ROUND((E14+F14)-H14,2) -> 7827.74
... A16: EMP015 | B16: =VLOOKUP(A16,payroll_management_db!A:B,2,0) -> Rohit | C16: 26000 | D16: 6 | E16: =ROUND((C16/31)*D16,2) -> 5032.26 | F16: =VLOOKUP(A16,payroll_management_db!A:H,8,0) -> 4160 | G16: =E16*3% -> 150.9678 | H16: =VLOOKUP(A16,payroll_management_db!A:J,10,0) -> 780 | I16: =ROUND((E16+F16)-H16,2) -> 8412.26

Sheet employee_payroll_system
A1: Emp_ID | B1: First_Name | C1: 1_Mon | D1: 2_Tue | E1: 3_Wed | F1: 4_Thu | G1: 5_Fri | H1: 6_Sat | I1: 7_Sun | J1: Total_Present | K1: Total_Absent | L1: Total_Leave | M1: Payable_Days
A2: EMP001 | B2: Rahul | C2: P | D2: P | E2: P | F2: P | G2: L | H2: H | I2: H | J2: =COUNTIF(C2:I2,"p") -> 4 | K2: =COUNTIF(C2:I2,"a") -> 0 | L2: =COUNTIF(C2:I2,"l") -> 1 | M2: =SUM(COUNTIF(C2:I2, "P"), COUNTIF(C2:I2, "L"), COUNTIF(C2:I2, "H")) -> 7
A3: EMP002 | B3: Simran | C3: P | D3: P | E3: P | F3: P | G3: P | H3: H | I3: H | J3: =COUNTIF(C3:I3,"p") -> 5 | K3: =COUNTIF(C3:I3,"a") -> 0 | L3: =COUNTIF(C3:I3,"l") -> 0 | M3: =SUM(COUNTIF(C3:I3, "P"), COUNTIF(C3:I3, "L"), COUNTIF(C3:I3, "H")) -> 7
A4: EMP003 | B4: Amit | C4: P | D4: P | E4: P | F4: P | G4: P | H4: H | I4: H | J4: =COUNTIF(C4:I4,"p") -> 5 | K4: =COUNTIF(C4:I4,"a") -> 0 | L4: =COUNTIF(C4:I4,"l") -> 0 | M4: =SUM(COUNTIF(C4:I4, "P"), COUNTIF(C4:I4, "L"), COUNTIF(C4:I4, "H")) -> 7
A5: EMP004 | B5: Neha | C5: L | D5: L | E5: P | F5: P | G5: P | H5: H | I5: H | J5: =COUNTIF(C5:I5,"p") -> 3 | K5: =COUNTIF(C5:I5,"a") -> 0 | L5: =COUNTIF(C5:I5,"l") -> 2 | M5: =SUM(COUNTIF(C5:I5, "P"), COUNTIF(C5:I5, "L"), COUNTIF(C5:I5, "H")) -> 7
A6: EMP005 | B6: Vikram | C6: P | D6: P | E6: P | F6: P | G6: P | H6: H | I6: H | J6: =COUNTIF(C6:I6,"p") -> 5 | K6: =COUNTIF(C6:I6,"a") -> 0 | L6: =COUNTIF(C6:I6,"l") -> 0 | M6: =SUM(COUNTIF(C6:I6, "P"), COUNTIF(C6:I6, "L"), COUNTIF(C6:I6, "H")) -> 7
A7: EMP006 | B7: Priya | C7: P | D7: P | E7: P | F7: L | G7: L | H7: H | I7: H | J7: =COUNTIF(C7:I7,"p") -> 3 | K7: =COUNTIF(C7:I7,"a") -> 0 | L7: =COUNTIF(C7:I7,"l") -> 2 | M7: =SUM(COUNTIF(C7:I7, "P"), COUNTIF(C7:I7, "L"), COUNTIF(C7:I7, "H")) -> 7
A8: EMP007 | B8: Ravi | C8: P | D8: P | E8: P | F8: P | G8: P | H8: H | I8: H | J8: =COUNTIF(C8:I8,"p") -> 5 | K8: =COUNTIF(C8:I8,"a") -> 0 | L8: =COUNTIF(C8:I8,"l") -> 0 | M8: =SUM(COUNTIF(C8:I8, "P"), COUNTIF(C8:I8, "L"), COUNTIF(C8:I8, "H")) -> 7
A9: EMP008 | B9: Gurpreet | C9: P | D9: P | E9: P | F9: P | G9: A | H9: H | I9: H | J9: =COUNTIF(C9:I9,"p") -> 4 | K9: =COUNTIF(C9:I9,"a") -> 1 | L9: =COUNTIF(C9:I9,"l") -> 0 | M9: =SUM(COUNTIF(C9:I9, "P"), COUNTIF(C9:I9, "L"), COUNTIF(C9:I9, "H")) -> 6
A10: EMP009 | B10: Aman | C10: P | D10: P | E10: P | F10: P | G10: P | H10: H | I10: H | J10: =COUNTIF(C10:I10,"p") -> 5 | K10: =COUNTIF(C10:I10,"a") -> 0 | L10: =COUNTIF(C10:I10,"l") -> 0 | M10: =SUM(COUNTIF(C10:I10, "P"), COUNTIF(C10:I10, "L"), COUNTIF(C10:I10, "H")) -> 7
A11: EMP010 | B11: Sonia | C11: P | D11: A | E11: A | F11: P | G11: P | H11: H | I11: H | J11: =COUNTIF(C11:I11,"p") -> 3 | K11: =COUNTIF(C11:I11,"a") -> 2 | L11: =COUNTIF(C11:I11,"l") -> 0 | M11: =SUM(COUNTIF(C11:I11, "P"), COUNTIF(C11:I11, "L"), COUNTIF(C11:I11, "H")) -> 5
A12: EMP011 | B12: Karan | C12: P | D12: P | E12: P | F12: P | G12: P | H12: H | I12: H | J12: =COUNTIF(C12:I12,"p") -> 5 | K12: =COUNTIF(C12:I12,"a") -> 0 | L12: =COUNTIF(C12:I12,"l") -> 0 | M12: =SUM(COUNTIF(C12:I12, "P"), COUNTIF(C12:I12, "L"), COUNTIF(C12:I12, "H")) -> 7
A13: EMP012 | B13: Pooja | C13: L | D13: P | E13: P | F13: P | G13: P | H13: H | I13: H | J13: =COUNTIF(C13:I13,"p") -> 4 | K13: =COUNTIF(C13:I13,"a") -> 0 | L13: =COUNTIF(C13:I13,"l") -> 1 | M13: =SUM(COUNTIF(C13:I13, "P"), COUNTIF(C13:I13, "L"), COUNTIF(C13:I13, "H")) -> 7
... A16: EMP015 | B16: Rohit | C16: A | D16: P | E16: P | F16: P | G16: P | H16: H | I16: H | J16: =COUNTIF(C16:I16,"p") -> 4 | K16: =COUNTIF(C16:I16,"a") -> 1 | L16: =COUNTIF(C16:I16,"l") -> 0 | M16: =SUM(COUNTIF(C16:I16, "P"), COUNTIF(C16:I16, "L"), COUNTIF(C16:I16, "H")) -> 6

Sheet pivot_db
A3: Row Labels | B3: Sum of Basic_Salary
A4: EMP001 | B4: 50000
A5: EMP002 | B5: 30000
A6: EMP003 | B6: 40000
A7: EMP004 | B7: 25000
A8: EMP005 | B8: 45000
A9: EMP006 | B9: 35000
A10: EMP007 | B10: 32000
A11: EMP008 | B11: 48000
A12: EMP009 | B12: 42000
A13: EMP010 | B13: 46000
A14: EMP011 | B14: 28000
A15: EMP012 | B15: 38000
... A19: Grand Total | B19: 562000
A22: Row Labels | B22: Sum of Basic_Salary
A23: Aman | B23: 42000
A24: Amit | B24: 40000
A25: Gurpreet | B25: 48000
A26: Harjit | B26: 22000
A27: Karan | B27: 28000
A28: Manpreet | B28: 55000
A29: Neha | B29: 25000
A30: Pooja | B30: 38000
A31: Priya | B31: 35000
A32: Rahul | B32: 50000
A33: Ravi | B33: 32000
A34: Rohit | B34: 26000
... A38: Grand Total | B38: 562000
A40: Sum of Basic_Salary
A41: 562000
A42: =GETPIVOTDATA("Basic_Salary",$A$40) -> 562000
A44: Row Labels
A45: EMP001
A46: EMP002
A47: EMP003
A48: EMP004
A49: EMP005
A50: EMP006
A51: EMP007
A52: EMP008
...

Sheet payslip
C1: Salary Slip
C4: Company Name
C5: Salary Slip
C7: Employee id: | E7: EMP008 | F7: Name | G7: =VLOOKUP(E7,payroll_management_db!A:K,2,0) -> Gurpreet | H7: Last Name | I7: =VLOOKUP(E7, payroll_management_db!A:K, 3, FALSE) -> Singh
C9: Department: | E9: =VLOOKUP(E7, payroll_management_db!A:K, 4, FALSE) -> Operations | H9: Designation: | I9: =VLOOKUP(E7, payroll_management_db!A:K, 5, FALSE) -> Manager
C10: Joining_Date | D10: =VLOOKUP(E7, payroll_management_db!A:K,6, FALSE) -> 14/06/2019 | E10: Bank_Account_No | F10: =VLOOKUP(E7,payroll_management_db!A:K,11,0) -> HDFC0001236 | H10: Aadhar no. | I10: =VLOOKUP(E7,payroll_management_db!A:L,12,0) -> 64646464764
C12: Earnings | E12: Amount | G12: Deductions | I12: Amount
C13: Basic Pay | E13: =VLOOKUP(E7, salary_process!A:I, 5, FALSE) -> 9290.32 | G13: PF Deduction | I13: =VLOOKUP(E7, salary_process!A:I, 8, FALSE) -> 1440
C14: HRA | E14: =VLOOKUP(E7, salary_process!A:I, 6, FALSE) -> 7680 | G14: ESI | I14: =VLOOKUP(E7, salary_process!A:H, 7, FALSE) -> 278.7096
C15: Special Allow. | E15: =VLOOKUP(E7, payroll_management_db!A:K, 9, FALSE) -> 2400
C16: Gross Earnings | E16: =SUM(E13:E15) -> 19370.32 | G16: Total Deduct. | I16: =I13+I14 -> 1718.7096
C17: NET PAY | D17: =E16-I16 -> 17651.61
